2020-05-24 19:09:19,077 INFO: Microblog startup [in /home/ioan/bin/microblog/app/__init__.py:30]
2020-05-24 19:09:52,836 INFO: Microblog startup [in /home/ioan/bin/microblog/app/__init__.py:30]
2020-05-24 19:09:56,738 ERROR: Exception on /edit_profile [POST] [in /home/ioan/bin/microblog/venv/lib/python3.8/site-packages/flask/app.py:1891]
Traceback (most recent call last):
  File "/home/ioan/bin/microblog/venv/lib/python3.8/site-packages/sqlalchemy/engine/base.py", line 1283, in _execute_context
    self.dialect.do_execute(
  File "/home/ioan/bin/microblog/venv/lib/python3.8/site-packages/sqlalchemy/engine/default.py", line 590, in do_execute
    cursor.execute(statement, parameters)
sqlite3.IntegrityError: UNIQUE constraint failed: user.username

The above exception was the direct cause of the following exception:

Traceback (most recent call last):
  File "/home/ioan/bin/microblog/venv/lib/python3.8/site-packages/flask/app.py", line 2447, in wsgi_app
    response = self.full_dispatch_request()
  File "/home/ioan/bin/microblog/venv/lib/python3.8/site-packages/flask/app.py", line 1952, in full_dispatch_request
    rv = self.handle_user_exception(e)
  File "/home/ioan/bin/microblog/venv/lib/python3.8/site-packages/flask/app.py", line 1821, in handle_user_exception
    reraise(exc_type, exc_value, tb)
  File "/home/ioan/bin/microblog/venv/lib/python3.8/site-packages/flask/_compat.py", line 39, in reraise
    raise value
  File "/home/ioan/bin/microblog/venv/lib/python3.8/site-packages/flask/app.py", line 1950, in full_dispatch_request
    rv = self.dispatch_request()
  File "/home/ioan/bin/microblog/venv/lib/python3.8/site-packages/flask/app.py", line 1936, in dispatch_request
    return self.view_functions[rule.endpoint](**req.view_args)
  File "/home/ioan/bin/microblog/venv/lib/python3.8/site-packages/flask_login/utils.py", line 272, in decorated_view
    return func(*args, **kwargs)
  File "/home/ioan/bin/microblog/app/routes.py", line 84, in edit_profile
    db.session.commit()
  File "/home/ioan/bin/microblog/venv/lib/python3.8/site-packages/sqlalchemy/orm/scoping.py", line 163, in do
    return getattr(self.registry(), name)(*args, **kwargs)
  File "/home/ioan/bin/microblog/venv/lib/python3.8/site-packages/sqlalchemy/orm/session.py", line 1042, in commit
    self.transaction.commit()
  File "/home/ioan/bin/microblog/venv/lib/python3.8/site-packages/sqlalchemy/orm/session.py", line 504, in commit
    self._prepare_impl()
  File "/home/ioan/bin/microblog/venv/lib/python3.8/site-packages/sqlalchemy/orm/session.py", line 483, in _prepare_impl
    self.session.flush()
  File "/home/ioan/bin/microblog/venv/lib/python3.8/site-packages/sqlalchemy/orm/session.py", line 2523, in flush
    self._flush(objects)
  File "/home/ioan/bin/microblog/venv/lib/python3.8/site-packages/sqlalchemy/orm/session.py", line 2664, in _flush
    transaction.rollback(_capture_exception=True)
  File "/home/ioan/bin/microblog/venv/lib/python3.8/site-packages/sqlalchemy/util/langhelpers.py", line 68, in __exit__
    compat.raise_(
  File "/home/ioan/bin/microblog/venv/lib/python3.8/site-packages/sqlalchemy/util/compat.py", line 178, in raise_
    raise exception
  File "/home/ioan/bin/microblog/venv/lib/python3.8/site-packages/sqlalchemy/orm/session.py", line 2624, in _flush
    flush_context.execute()
  File "/home/ioan/bin/microblog/venv/lib/python3.8/site-packages/sqlalchemy/orm/unitofwork.py", line 422, in execute
    rec.execute(self)
  File "/home/ioan/bin/microblog/venv/lib/python3.8/site-packages/sqlalchemy/orm/unitofwork.py", line 586, in execute
    persistence.save_obj(
  File "/home/ioan/bin/microblog/venv/lib/python3.8/site-packages/sqlalchemy/orm/persistence.py", line 230, in save_obj
    _emit_update_statements(
  File "/home/ioan/bin/microblog/venv/lib/python3.8/site-packages/sqlalchemy/orm/persistence.py", line 994, in _emit_update_statements
    c = cached_connections[connection].execute(
  File "/home/ioan/bin/microblog/venv/lib/python3.8/site-packages/sqlalchemy/engine/base.py", line 1020, in execute
    return meth(self, multiparams, params)
  File "/home/ioan/bin/microblog/venv/lib/python3.8/site-packages/sqlalchemy/sql/elements.py", line 298, in _execute_on_connection
    return connection._execute_clauseelement(self, multiparams, params)
  File "/home/ioan/bin/microblog/venv/lib/python3.8/site-packages/sqlalchemy/engine/base.py", line 1133, in _execute_clauseelement
    ret = self._execute_context(
  File "/home/ioan/bin/microblog/venv/lib/python3.8/site-packages/sqlalchemy/engine/base.py", line 1323, in _execute_context
    self._handle_dbapi_exception(
  File "/home/ioan/bin/microblog/venv/lib/python3.8/site-packages/sqlalchemy/engine/base.py", line 1517, in _handle_dbapi_exception
    util.raise_(
  File "/home/ioan/bin/microblog/venv/lib/python3.8/site-packages/sqlalchemy/util/compat.py", line 178, in raise_
    raise exception
  File "/home/ioan/bin/microblog/venv/lib/python3.8/site-packages/sqlalchemy/engine/base.py", line 1283, in _execute_context
    self.dialect.do_execute(
  File "/home/ioan/bin/microblog/venv/lib/python3.8/site-packages/sqlalchemy/engine/default.py", line 590, in do_execute
    cursor.execute(statement, parameters)
sqlalchemy.exc.IntegrityError: (sqlite3.IntegrityError) UNIQUE constraint failed: user.username
[SQL: UPDATE user SET username=?, about_me=? WHERE user.id = ?]
[parameters: ('coco', '', 3)]
(Background on this error at: http://sqlalche.me/e/gkpj)
2020-05-24 19:13:55,061 INFO: Microblog startup [in /home/ioan/bin/microblog/app/__init__.py:30]
2020-05-24 19:21:39,055 INFO: Microblog startup [in /home/ioan/bin/microblog/app/__init__.py:30]
2020-05-24 19:21:45,562 INFO: Microblog startup [in /home/ioan/bin/microblog/app/__init__.py:30]
2020-05-24 19:22:17,946 INFO: Microblog startup [in /home/ioan/bin/microblog/app/__init__.py:30]
2020-05-24 19:22:28,636 INFO: Microblog startup [in /home/ioan/bin/microblog/app/__init__.py:30]
2020-05-24 19:22:32,345 INFO: Microblog startup [in /home/ioan/bin/microblog/app/__init__.py:30]
2020-05-24 19:33:37,847 INFO: Microblog startup [in /home/ioan/bin/microblog/app/__init__.py:30]
2020-05-24 19:35:25,259 INFO: Microblog startup [in /home/ioan/bin/microblog/app/__init__.py:30]
2020-05-24 19:36:32,185 INFO: Microblog startup [in /home/ioan/bin/microblog/app/__init__.py:30]
2020-05-24 19:36:52,482 INFO: Microblog startup [in /home/ioan/bin/microblog/app/__init__.py:30]
2020-05-24 19:37:23,362 INFO: Microblog startup [in /home/ioan/bin/microblog/app/__init__.py:30]
2020-05-24 19:39:37,012 INFO: Microblog startup [in /home/ioan/bin/microblog/app/__init__.py:30]
2020-05-24 19:39:54,568 INFO: Microblog startup [in /home/ioan/bin/microblog/app/__init__.py:30]
2020-05-24 19:49:11,269 INFO: Microblog startup [in /home/ioan/bin/microblog/app/__init__.py:30]
2020-05-24 19:49:17,465 INFO: Microblog startup [in /home/ioan/bin/microblog/app/__init__.py:30]
2020-05-24 19:51:10,372 INFO: Microblog startup [in /home/ioan/bin/microblog/app/__init__.py:30]
2020-05-24 19:52:02,853 ERROR: Exception on /user/coco [GET] [in /home/ioan/bin/microblog/venv/lib/python3.8/site-packages/flask/app.py:1891]
Traceback (most recent call last):
  File "/home/ioan/bin/microblog/venv/lib/python3.8/site-packages/flask/app.py", line 2447, in wsgi_app
    response = self.full_dispatch_request()
  File "/home/ioan/bin/microblog/venv/lib/python3.8/site-packages/flask/app.py", line 1952, in full_dispatch_request
    rv = self.handle_user_exception(e)
  File "/home/ioan/bin/microblog/venv/lib/python3.8/site-packages/flask/app.py", line 1821, in handle_user_exception
    reraise(exc_type, exc_value, tb)
  File "/home/ioan/bin/microblog/venv/lib/python3.8/site-packages/flask/_compat.py", line 39, in reraise
    raise value
  File "/home/ioan/bin/microblog/venv/lib/python3.8/site-packages/flask/app.py", line 1950, in full_dispatch_request
    rv = self.dispatch_request()
  File "/home/ioan/bin/microblog/venv/lib/python3.8/site-packages/flask/app.py", line 1936, in dispatch_request
    return self.view_functions[rule.endpoint](**req.view_args)
  File "/home/ioan/bin/microblog/venv/lib/python3.8/site-packages/flask_login/utils.py", line 272, in decorated_view
    return func(*args, **kwargs)
  File "/home/ioan/bin/microblog/app/routes.py", line 70, in user
    return render_template('user.html', user=user, posts=posts, form=form)
  File "/home/ioan/bin/microblog/venv/lib/python3.8/site-packages/flask/templating.py", line 137, in render_template
    return _render(
  File "/home/ioan/bin/microblog/venv/lib/python3.8/site-packages/flask/templating.py", line 120, in _render
    rv = template.render(context)
  File "/home/ioan/bin/microblog/venv/lib/python3.8/site-packages/jinja2/environment.py", line 1090, in render
    self.environment.handle_exception()
  File "/home/ioan/bin/microblog/venv/lib/python3.8/site-packages/jinja2/environment.py", line 832, in handle_exception
    reraise(*rewrite_traceback_stack(source=source))
  File "/home/ioan/bin/microblog/venv/lib/python3.8/site-packages/jinja2/_compat.py", line 28, in reraise
    raise value.with_traceback(tb)
  File "/home/ioan/bin/microblog/app/templates/user.html", line 1, in top-level template code
    {% extends "base.html" %}
  File "/home/ioan/bin/microblog/app/templates/base.html", line 30, in top-level template code
    {% block content %}{% endblock %}
  File "/home/ioan/bin/microblog/app/templates/user.html", line 18, in block "content"
    {{ form.submit(value='Follow') }}
jinja2.exceptions.UndefinedError: 'app.forms.EmptyForm object' has no attribute 'submit'
